Workbook
Name _ftn1: 'riwayat hidup personil'!#REF!
Name _ftnref1: 'riwayat hidup personil'!$B$14

Sheet Daftar Pengalaman Kerja
A2: G. | B2: Daftar Pengalaman Kerja Sejenis 10 (Sepuluh) Tahun Terakhir
A4: No. | B4: Pengguna Jasa/ Sumber Dana | C4: Nama Paket Pekerjaan | D4: Lingkup Layanan | E4: Periode | F4: Orang Bulan | G4: Nilai Kontrak | H4: Mitra Keja
A6: 1 | B6: 2 | C6: 3 | D6: 4 | E6: 5 | F6: 6 | G6: 7 | H6: 8
A8: 1 | B8: Dinas Pendidikan, Kebudayaan, Pemuda dan Olahraga | C8: 1. Perencanaan Rehabilitasi Ruang Belajar SMUN 03 Mamuju Utara | D8: Jasa Konsultansi | E8: 41388 | G8: 36960000
C9: 2. Perencanaan Rehabilitasi Ruang Belajar SMUN 04 Mamuju Utara | E9: s/d
C10: 3. Perencanaan Rehabilitasi Ruang Belajar SMUN 05 Mamuju Utara | E10: 41417
C11: 4. Perencanaan Rehabilitasi Ruang Belajar SMUN 06 Mamuju Utara
A13: 2 | B13: Dinas PU Kab. Mamuju Utara | C13: 1. Perencanaan Jembatan Wirabuana | D13: Jasa Konsultansi | E13: 41402 | G13: 39891000
C14: 2. Perencanaan Jembatan Todai | E14: s/d
C15: 3. Perencanaan Jembatan Saluwu Kaluku Nagka | E15: 41432
A17: 3 | B17: Dinas PU Kab. Mamuju Utara | C17: 1. Perencanaan Pembangunan Saluran Pembuang Desa Sarudu | D17: Jasa Konsultansi | E17: 41359 | G17: 44533000
C18: 2. Perencanaan Pembangunan Saluran Pembuang Dusun Sinar Wajo Desa Karya Bersama | E18: s/d
C19: 3. Perencanaan Pembangunan Saluran Pembuang Dusun Marembeau Desa Karya Bersama | E19: 41388
C20: 4. Perencanaan Saluran Pembuang Kel.Bambalamotu
C21: 5.Perencanaan Pembangunan Saluran Pembuang Dusun Sempo Selatan
C22: 6. Perencanaan Pembangunan Saluran Pembuang Salunggaluku Desa Randomayang
C23: 7. Perencanaan Normalisasi Sungai Tikke
C24: 8. Perencanaan Pembangunan Saluran Pembuang Dusun Tamaallo Desa Sarudu
C25: 9. Perencanaan Normalisasi Sungai Karave
C26: 10. Perencanaan Normalisasi Saluran Kampung Maros
C27: 11. Perencanaan Normalisasi Saluran Tamaallo Desa Bulu Mario
A29: 4 | B29: Dinas PU Kab. Mamuju Utara | C29: 1. Perencanaan Pembukaan Jalan Watu-wete Bulai | D29: Jasa Konsultansi | E29: 41715 | G29: 10252000
C30: 2. Perencanaan Pembukaan Jalan Kuma Sarudu | E30: s/d
E31: 41744
A34: 6 | B34: Dinas PU Kab. Mamuju Utara | C34: 1. Perencanaan Peningkatan Jalan Rojo Dusun Pangale | D34: Jasa Konsultansi | E34: 41715 | G34: 19046000
C35: 2. Perencanaan Peningkatan Jalan Tamarunang SP5 | E35: s/d
E36: 41744
A39: 7 | B39: Sekretariat Daerah Kab. Mamuju Utara | C39: Jasa Konsultansi Perencanaan Teknis Landscape Kantor Kecamatan Tikke Raya | D39: Jasa Konsultansi | E39: 41918 | G39: 39990000
E40: s/d
E41: 41948
A44: 8 | B44: Sekretariat Daerah Kab. Mamuju Utara | C44: Perencanaan Teknis Landscape Kantor Kecamatan Doripoku | D44: Jasa Konsultansi | E44: 41918 | G44: 39970000
E45: s/d
E46: 41948
A49: 9 | B49: Sekretariat Daerah Kab. Mamuju Utara | C49: Jasa Konsultansi Perencanaan Renovasi Total Kantor Camat Baras | D49: Jasa Konsultansi | E49: 41918 | G49: 18000000
E50: s/d
E51: 41948
A53: 10. | B53: Dinas PU Kab. Mamuju Utara | C53: Perencanaan Peningkatan Jalan Hotmix Desa Letawa | D53: Jasa Konsultansi | E53: 41918 | G53: 49720000
E54: s/d
E55: 41944
A57: 11. | B57: Dinas PU Kab. Mamuju Utara | C57: Perencanaan Peningkatan Jalan Hotmix Dusun Jono Desa Tikke | D57: Jasa Konsultansi | E57: 41926 | G57: 49720000
...

Sheet Uraian Pengalaman
A1: URAIAN PENGALAMAN KERJA SEJENIS
A2: 10 (SEPULUH) TAHUN TERAKHIR
A3: 1. | B3: Pengguna jasa | F3: : | G3: Dinas Pendidikan, Kebudayaan, Pemuda dan Olahraga
A4: 2. | B4: Nama Paket Pekerjaan | F4: : | G4: Perencanaan Rehabilitasi Ruang Belajar SMUN 03 Mamuju Utara, Perencanaan Rehabilitasi Ruang Belajar SMUN 04 Mamuju Utara, Perencanaan Rehabilitasi Ruang Belajar SMUN 05 Mamuju Utara, Perencanaan Rehabilitasi Ruang Belajar SMUN 06 Mamuju Utara.
A5: 3. | B5: Lingkup Produk Utama | F5: : | G5: Perencanaan
A6: 4. | B6: Lokasi Proyek | F6: : | G6: Kota Pasangkayu Mamuju Utara
A7: 5. | B7: Nilai Kontrak | F7: : | G7: Rp. 36.960.000,-
A8: 6. | B8: No. Kontrak | F8: : | G8: 410/13/Kont-Konsult.Prc/Pgd.L-DAU/IV/2013
A9: 7. | B9: Waktu Pelaksanaan | F9: : | G9: 24 April s/d 23 Mei 2013
A10: 8. | B10: Nama Perusahaan Utama (Led Firm) | F10: : | G10: CV.TOHA PRATAMA
B11: Alamat | F11: : | G11: Jln. Basuki Rahmat Lrg.Saleko I No.110c
B12: Negara Asal | F12: : | G12: Indonesia
A13: 9. | B13: Jumlah Tenaga ahli : | E13: Tenaga Ahli Asing | I13: : | J13: 0 | K13: Orang Bulan
E14: Tenaga Ahli Indonesia | I14: : | J14: 2 | K14: Orang Bulan
A15: 10. | B15: Perusahaan Mitra Kerja | H15: Jumlah Tenaga Ahli
J16: Asing | N16: Indonesia
B17: a. (Nama Perusahaan) | F17: : | J17: Orang Bulan | O17: Orang Bulan
B18: b. (Nama Perusahaan) | F18: : | J18: Orang Bulan | O18: Orang Bulan
B19: c. (Nama Perusahaan) | F19: : | J19: Orang Bulan | O19: Orang Bulan
B20: d. (Nama Perusahaan) | F20: : | J20: Orang Bulan | O20: Orang Bulan
B21: dst
B22: Tenaga ahli tetap yang terlibat :
D23: Posisi | H23: Keahlian | N23: Jumlah Orang Bulan
B24: a. | C24: Ketua Tim | G24: Teknik Sipil | M24: 1
B25: b. | C25: Tenaga Lapangan | G25: Teknik Sipil | M25: 1
B26: c. | C26: Tenaga Lapangan
B27: d. | C27: Pengolah Data
A32: URAIAN PENGALAMAN KERJA SEJENIS
A33: 10 (SEPULUH) TAHUN TERAKHIR
A34: 1. | B34: Pengguna jasa | F34: : | G34: Dinas PU Kab. Mamuju Utara
A35: 2. | B35: Nama Paket Pekerjaan | F35: : | G35: Perencanaan Pembangunan Saluran Pembuang Desa Sarudu, Perencanaan Pembangunan Saluran Pembuang Dusun Sinar Wajo Desa Karya Bersama, Perencanaan Pembangunan Saluran Pembuang Dusun Marembeau Desa Karya Bersama, Perencanaan Saluran Pembuang Kel.Bambalamotu, Perencanaan Pembangunan Saluran Pembuang Dusun Sempo Selatan, Perencanaan Pembangunan Saluran Pembuang Salunggaluku Desa Randomayang, Perencanaan Normalisasi Sungai Tikke, Perencanaan Pembangunan Saluran Pembuang Dusun Tamaallo Desa Sarudu, Perencanaan Normalisasi Sungai Karave, Perencanaan Normalisasi Saluran Kampung Maros, Perencanaan Normalisasi Saluran Tamaallo Desa Bulu Mario.
A36: 3. | B36: Lingkup Produk Utama | F36: : | G36: Perencanaan
A37: 4. | B37: Lokasi Proyek | F37: : | G37: Kota Pasangkayu Mamuju Utara
A38: 5. | B38: Nilai Kontrak | F38: : | G38: Rp. 44.533.000,-
A39: 6. | B39: No. Kontrak | F39: : | G39: 600/041/SPK-KONSULTAN/PPK/III/2013/DPU
A40: 7. | B40: Waktu Pelaksanaan | F40: : | G40: 26 Maret s/d 24 April 2013
A41: 8. | B41: Nama Perusahaan Utama (Led Firm) | F41: : | G41: CV.TOHA PRATAMA
B42: Alamat | F42: : | G42: Jln. Basuki Rahmat Lrg.Saleko I No.110c
B43: Negara Asal | F43: : | G43: Indonesia
A44: 9. | B44: Jumlah Tenaga ahli : | E44: Tenaga Ahli Asing | I44: : | J44: 0 | K44: Orang Bulan
...

Sheet jadwal pelaksanaan
A1: 3. | B1: Jadwal Pelaksanaan Pekerjaan
A3: No. | B3: Kegiatan | C3: Maret | G3: Maret | K3: Keterangan
C4: I | D4: II | E4: III | F4: IV | G4: I | H4: II | I4: III | J4: IV
A5: 1 | B5: 2 | C5: 3 | D5: 4 | E5: 5 | F5: 6 | G5: 3 | H5: 4 | I5: 5 | J5: 6 | K5: 7
A7: 1 | B7: Pekerjaan Persiapan : Mobilisasi Peralatan dan Personil
A10: 2 | B10: Perumusan Metode dan Strategi Pelaksanaan Kegiatan
A12: 3 | B12: Survey Investigasi :
B13: - Pengukuran Lokasi
B14: - Pemeriksaan Tanah
A15: 4 | B15: Penyusunan Inception Report
A16: 5 | B16: Pembuatan Gambar Desain Jalan
A17: 6 | B17: Analisa Perhitungan Struktur : Hasil Perhitungan
A18: 7 | B18: Pengecekan Gambar Desain dan Pembuatan Perspektif / Detail Jalan
A19: 8 | B19: Monitoring Pelaksanaan Kegiatan Perencanaan
A20: 9 | B20: Asistensi Pekerjaan dengan Pihak Proyek : Pekerjaan Revisi atau Dilanjutkan
A21: 10 | B21: Penyusunan Konsep Laporan Akhir
A22: 11 | B22: Pembuatan Gambar DED Final dan Pencetakan Gambar
A23: 12 | B23: Penyusunan Engineering Estimate
A24: 13 | B24: Penyusunan Resume Kegiatan dan Pembuatan Laporan Akhir
A25: 14 | B25: Penggandaan Laporan, Gambar Kerja, Engineering Estimate (RAB)
A26: 15 | B26: Penyerahan Laporan Akhir (Pekerjaan Selesai)
K29: Pasangkayu, 21 Februari 2024
J30: CV. TOHA PRATAMA
J35: ANDI NUR FAISAL, ST
J36: ='Daftar Pengalaman Kerja'!G81:G81 -> Direktur

Sheet komposisi tim
A2: 4. | B2: Komposisi Tim dan Penugasan (Daftar Personil)
B4: Tenaga Ahli
B5: (Personil Inti)
A7: No | B7: Nama Personil | C7: Perusahaan | D7: Tenaga Ahli Lokal/Asing | E7: Lingkup Keahlian | F7: Posisi Diusulkan | G7: Uraian Pekerjaan | H7: Jumlah Orang Bulan
A9: 1 | B9: ='pernyataan kesediaan'!D4 -> Ir.Fatmawati | C9: CV.TOHA PRATAMA | D9: Lokal | E9: Teknik Sipil | F9: Team Leader | G9: Managerial | H9: 1
A13: 2 | B13: ='pernyataan kesediaan'!D39 -> Deddy Sanjaya Rioeh,ST | C13: CV.TOHA PRATAMA | D13: Lokal | E13: Teknik Sipil | F13: Ahli Sipil Transportasi | G13: Managerial | H13: 1
B15: Sub Profesional Staff
B16: (Personil Lainnya)
A18: No | B18: Nama Personil | C18: Perusahaan | D18: Tenaga Ahli Lokal/Asing | E18: Lingkup Keahlian | F18: Posisi Diusulkan | G18: Uraian Pekerjaan | H18: Jumlah Orang Bulan
A20: 1 | B20: Zulkifli, ST | C20: =C9 -> CV.TOHA PRATAMA | D20: Lokal | E20: Surveyor | F20: Surveyor | G20: Survey | H20: 1
A21: 2 | B21: Moh.Safar, ST | C21: =C20 -> CV.TOHA PRATAMA | D21: Lokal | E21: CAD/CAM Operator | F21: CAD/CAM Operator | G21: Juru gambar | H21: 1
A22: 3 | B22: Iswanto, ST | C22: =C21 -> CV.TOHA PRATAMA | D22: Lokal | E22: Tenaga Teknis Mektan | F22: Tenaga Teknis Mektan | G22: Tenaga Teknis Mektan | H22: 1
B24: Supporting Personil Staff
B25: (Personil Pendukung)
A27: No | B27: Nama Personil | C27: Perusahaan | D27: Tenaga Ahli Lokal/Asing | E27: Lingkup Keahlian | F27: Posisi Diusulkan | G27: Uraian Pekerjaan | H27: Jumlah Orang Bulan
A29: 1 | B29: Rahmon | C29: =C20 -> CV.TOHA PRATAMA | D29: Lokal | E29: Pembantu Pengukuran | F29: Pembantu Pengukuran | G29: Pembantu Pengukuran | H29: 1
A30: 2 | B30: Zulfikar | C30: =C29 -> CV.TOHA PRATAMA | D30: Lokal | E30: Pembantu Tenaga Mektan | F30: Pembantu Tenaga Mektan | G30: Pembantu Tenaga Mektan | H30: 1
A31: 3 | B31: Hedi | C31: =C30 -> CV.TOHA PRATAMA | D31: Lokal | E31: Administrasi | F31: Administrator | G31: Administrasi | H31: 1

Sheet Jadwal Penugasan
A1: 5. | B1: Jadwal Penugasan Tenaga Ahli
A3: No. | B3: Nama Personil | C3: Masukan Personil | G3: Orang Bulan
C5: 1 | D5: 2 | E5: 3 | F5: 4
A6: Nasional
A7: 1 | B7: ='komposisi tim'!B9 -> Ir.Fatmawati | G7: 1
A8: 2 | B8: ='komposisi tim'!B20 -> Zulkifli, ST | G8: 1
A9: 3 | B9: ='komposisi tim'!B21 -> Moh.Safar, ST | G9: 1
A10: 4 | B10: ='komposisi tim'!B22 -> Iswanto, ST | G10: 1
G11: =SUM(G7:I10) -> 4
B14: Masukan Penuh - Waktu | E14: Masukan Paruh - Waktu
H18: ='Daftar Pengalaman Kerja'!G74 -> Pasangkayu, 13 Februari 2015
F19: ='Daftar Pengalaman Kerja'!G75 -> CV.TOHA PRATAMA
F24: ='Daftar Pengalaman Kerja'!G80 -> ANDI NUR FAISAL, ST
F25: ='Daftar Pengalaman Kerja'!G81 -> Direktur

Sheet riwayat hidup personil
A2: 1. | B2: Daftar Riwayat Hidup Personil Yang Diusulkan
A4: 1. | B4: Posisi yang diusulkan | E4: : | F4: Ketua Tim | M4: 1. | N4: Posisi yang diusulkan | Q4: : | R4: Ahli Sipil | Y4: 1. | Z4: Posisi yang diusulkan | AC4: : | AD4: Ahli Arsitektur | AK4: 1. | AL4: Posisi yang diusulkan | AO4: : | AP4: =AD4 -> Ahli Arsitektur | AW4: 1. | AX4: Posisi yang diusulkan | BA4: : | BB4: Ahli Sipil | BI4: 1. | BJ4: Posisi yang diusulkan | BM4: :
A5: 2. | B5: Nama Perusahaan | E5: : | F5: CV. Adicipta Nusatama | M5: 2. | N5: Nama Perusahaan | Q5: : | R5: CV. Adicipta Nusatama | Y5: 2. | Z5: Nama Perusahaan | AC5: : | AD5: CV. Adicipta Nusatama | AK5: 2. | AL5: Nama Perusahaan | AO5: : | AP5: CV. Adicipta Nustama | AW5: 2. | AX5: Nama Perusahaan | BA5: : | BB5: CV. Adicipta Nusatama | BI5: 2. | BJ5: Nama Perusahaan | BM5: :
A6: 3. | B6: Nama Personil | E6: : | F6: Taufik K. Palenga, ST | M6: 3. | N6: Nama Personil | Q6: : | R6: Husin, ST | Y6: 3. | Z6: Nama Personil | AC6: : | AD6: Ir. Irwan, IAI | AK6: 3. | AL6: Nama Personil | AO6: : | AP6: ='komposisi tim'!B12 -> 0 | AW6: 3. | AX6: Nama Personil | BA6: : | BB6: Fikri, ST | BI6: 3. | BJ6: Nama Personil | BM6: :
A7: 4. | B7: Tempat/Tanggal Lahir | E7: : | F7: Kilo/ 05 Juli 1969 | M7: 4. | N7: Tempat/Tanggal Lahir | Q7: : | R7: Soppeng/02 Agustus 1974 | Y7: 4. | Z7: Tempat/Tanggal Lahir | AC7: : | AD7: Jakarta/22 Juni 1972 | AK7: 4. | AL7: Tempat/Tanggal Lahir | AO7: : | AP7: Padang, 18 April 1963 | AW7: 4. | AX7: Tempat/Tanggal Lahir | BA7: : | BB7: Manado/27 Maret 1976 | BI7: 4. | BJ7: Tempat/Tanggal Lahir | BM7: :
A8: 5. | B8: Pendidikan (Lembaga pendidikan, | M8: 5. | N8: Pendidikan (Lembaga pendidikan, | Y8: 5. | Z8: Pendidikan (Lembaga pendidikan, | AK8: 5. | AL8: Pendidikan (Lembaga pendidikan, | AW8: 5. | AX8: Pendidikan (Lembaga pendidikan, | BI8: 5. | BJ8: Pendidikan (Lembaga pendidikan,
B9: tempat dan tahun tamat belajar, | N9: tempat dan tahun tamat belajar, | Z9: tempat dan tahun tamat belajar, | AL9: tempat dan tahun tamat belajar, | AX9: tempat dan tahun tamat belajar, | BJ9: tempat dan tahun tamat belajar,
B10: dilampirkan rekaman ijazah ) | E10: : | F10: Untad Palu, 20 Maret 2000 | N10: dilampirkan rekaman ijazah ) | Q10: : | R10: Universitas Hasanuddin, Makasar, 25 Nopember 2000 | Z10: dilampirkan rekaman ijazah ) | AC10: : | AD10: Universitas Muslim Indonesia, Maksar, 26 Pebruari 2000 | AL10: dilampirkan rekaman ijazah ) | AO10: : | AP10: Univ. Katolik Parahyangan Bandung, 18 April, 2000 | AX10: dilampirkan rekaman ijazah ) | BA10: : | BB10: Universitas Muslim Indonesia Makasar, 11 Mei 2002 | BJ10: dilampirkan rekaman ijazah ) | BM10: :
A11: 6. | B11: Pendidikan Non Formal | E11: : | F11: Pelatihan Asosiasi Tenaga Ahli Konstruksi Indonesia | M11: 6. | N11: Pendidikan Non Formal | Q11: : | R11: =F11 -> Pelatihan Asosiasi Tenaga Ahli Konstruksi Indonesia | Y11: 6. | Z11: Pendidikan Non Formal | AC11: : | AD11: Pelatihan Ikatan Arsitek Indonesia | AK11: 6. | AL11: Pendidikan Non Formal | AO11: : | AP11: =AD11 -> Pelatihan Ikatan Arsitek Indonesia | AW11: 6. | AX11: Pendidikan Non Formal | BA11: : | BB11: Pelatihan Ikatan Ahli Perencanaan Indonesia | BI11: 6. | BJ11: Pendidikan Non Formal | BM11: :
A12: 7. | B12: Penguasaan Bahasa Inggris | M12: 7. | N12: Penguasaan Bahasa Inggris | Y12: 7. | Z12: Penguasaan Bahasa Inggris | AK12: 7. | AL12: Penguasaan Bahasa Inggris | AW12: 7. | AX12: Penguasaan Bahasa Inggris | BI12: 7. | BJ12: Penguasaan Bahasa Inggris
A13: dan bahasa Indonesia | B13: dan Bahasa Indonesia | E13: : | F13: Baik | M13: dan bahasa Indonesia | N13: dan Bahasa Indonesia | Q13: : | R13: Baik | Y13: dan bahasa Indonesia | Z13: dan Bahasa Indonesia | AC13: : | AD13: Baik | AK13: dan bahasa Indonesia | AL13: dan Bahasa Indonesia | AO13: : | AP13: Baik | AW13: dan bahasa Indonesia | AX13: dan Bahasa Indonesia | BA13: : | BB13: =AP13 -> Baik | BI13: dan bahasa Indonesia | BJ13: dan Bahasa Indonesia | BM13: :
A14: 8. | B14: Pengalaman Kerja | M14: 8. | N14: Pengalaman Kerja | Y14: 8. | Z14: Pengalaman Kerja | AK14: 8. | AL14: Pengalaman Kerja | AW14: 8. | AX14: Pengalaman Kerja | BI14: 8. | BJ14: Pengalaman Kerja
A15: Tahun ini ____ | B15: Tahun | D15: 2011 | M15: Tahun ini ____ | N15: Tahun | P15: 2011 | Y15: Tahun ini ____ | Z15: Tahun | AB15: 2011 | AK15: Tahun ini ____ | AL15: Tahun | AN15: 2011 | AW15: Tahun ini ____ | AX15: Tahun | AZ15: 2011 | BI15: Tahun ini ____ | BJ15: Tahun | BL15: 2011
B16: a. | C16: Nama Proyek | E16: : | F16: Perencanaan Teknis Peningkatan Jalan Hi. Hayun | N16: a. | O16: Nama Proyek | Q16: : | R16: =F16 -> Perencanaan Teknis Peningkatan Jalan Hi. Hayun | Z16: a. | AA16: Nama Proyek | AC16: : | AD16: =R16 -> Perencanaan Teknis Peningkatan Jalan Hi. Hayun | AL16: a. | AM16: Nama Proyek | AO16: : | AP16: =AD16 -> Perencanaan Teknis Peningkatan Jalan Hi. Hayun | AX16: a. | AY16: Nama Proyek | BA16: : | BB16: =AP16 -> Perencanaan Teknis Peningkatan Jalan Hi. Hayun | BJ16: a. | BK16: Nama Proyek | BM16: :
B17: b. Lokasi Proyek | C17: Lokasi Proyek | E17: : | F17: Kab. Tolitoli | N17: b. Lokasi Proyek | O17: Lokasi Proyek | Q17: : | R17: =F17 -> Kab. Tolitoli | Z17: b. Lokasi Proyek | AA17: Lokasi Proyek | AC17: : | AD17: =R17 -> Kab. Tolitoli | AL17: b. Lokasi Proyek | AM17: Lokasi Proyek | AO17: : | AP17: =AD17 -> Kab. Tolitoli | AX17: b. Lokasi Proyek | AY17: Lokasi Proyek | BA17: : | BB17: =AP17 -> Kab. Tolitoli | BJ17: b. Lokasi Proyek | BK17: Lokasi Proyek | BM17: :
B18: c. Pengguna Jasa | C18: Pengguna Jasa | E18: : | F18: Dinas PU Kab. Tolitoli | N18: c. Pengguna Jasa | O18: Pengguna Jasa | Q18: : | R18: =F18 -> Dinas PU Kab. Tolitoli | Z18: c. Pengguna Jasa | AA18: Pengguna Jasa | AC18: : | AD18: =R18 -> Dinas PU Kab. Tolitoli | AL18: c. Pengguna Jasa | AM18: Pengguna Jasa | AO18: : | AP18: =AD18 -> Dinas PU Kab. Tolitoli | AX18: c. Pengguna Jasa | AY18: Pengguna Jasa | BA18: : | BB18: =AP18 -> Dinas PU Kab. Tolitoli | BJ18: c. Pengguna Jasa | BK18: Pengguna Jasa | BM18: :
B19: d. Nama Perusahaan | C19: Nama Perusahaan | E19: : | F19: =F5 -> CV. Adicipta Nusatama | N19: d. Nama Perusahaan | O19: Nama Perusahaan | Q19: : | R19: =F19 -> CV. Adicipta Nusatama | Z19: d. Nama Perusahaan | AA19: Nama Perusahaan | AC19: : | AD19: =R19 -> CV. Adicipta Nusatama | AL19: d. Nama Perusahaan | AM19: Nama Perusahaan | AO19: : | AP19: =AD19 -> CV. Adicipta Nusatama | AX19: d. Nama Perusahaan | AY19: Nama Perusahaan | BA19: : | BB19: =AP19 -> CV. Adicipta Nusatama | BJ19: d. Nama Perusahaan | BK19: Nama Perusahaan | BM19: :
B20: e. | C20: Uraian Tugas | E20: : | F20: - Membuat dan menghitung desain struktur konstruksi yang kokoh namun ekonomis, | N20: e. Uraian Tugas | O20: Uraian Tugas | Q20: : | R20: - Bersama Team Leader membuat dan menghitung desain struktur konstruksi yang kokoh namun ekonomis, | Z20: e. | AA20: Uraian Tugas | AC20: : | AD20: - Bersama Team Leader membuat dan menghitung desain struktur konstruksi yang kokoh namun ekonomis, | AL20: e. Uraian Tugas | AM20: Uraian Tugas | AO20: : | AP20: - Bersama Team Leader membuat dan menghitung desain struktur konstruksi yang kokoh namun ekonomis, | AX20: e. Uraian Tugas | AY20: Uraian Tugas | BA20: : | BB20: - Bersama Team Leader membuat dan menghitung desain struktur konstruksi yang kokoh namun ekonomis, | BJ20: e. Uraian Tugas | BK20: Uraian Tugas | BM20: :
F21: - Melakukan asistensi kepada pemberi tugas terhadap desain yang telah dikerjakan, | R21: - Bersama Team Leader Melakukan asistensi kepada pemberi tugas terhadap desain yang telah dikerjakan, | AD21: - Bersama Team Leader Melakukan asistensi kepada pemberi tugas terhadap desain yang telah dikerjakan, | AP21: - Bersama Team Leader Melakukan asistensi kepada pemberi tugas terhadap desain yang telah dikerjakan, | BB21: - Bersama Team Leader Melakukan asistensi kepada pemberi tugas terhadap desain yang telah dikerjakan,
F22: - Membuat laporan maupun dokumen struktur lainnya, | R22: - Membantu Leader Membuat laporan maupun dokumen struktur lainnya, | AD22: - Membantu Leader Membuat laporan maupun dokumen struktur lainnya, | AP22: - Membantu Leader Membuat laporan maupun dokumen struktur lainnya, | BB22: - Membantu Leader Membuat laporan maupun dokumen struktur lainnya,
F23: - Bersama personil lainnya melakukan ekspose terhadap desain yang telah dihasilkan, | R23: - Bersama personil lainnya melakukan ekspose terhadap desain yang telah dihasilkan, | AD23: - Bersama personil lainnya melakukan ekspose terhadap desain yang telah dihasilkan, | AP23: - Bersama personil lainnya melakukan ekspose terhadap desain yang telah dihasilkan, | BB23: - Bersama personil lainnya melakukan ekspose terhadap desain yang telah dihasilkan,
F24: - Membuat/menyusun dokumen lelang untuk pelaksanaan fisik. | R24: - Membantu Team Leader Membuat/menyusun dokumen lelang untuk pelaksanaan fisik. | AD24: - Membantu Team Leader Membuat/menyusun dokumen lelang untuk pelaksanaan fisik. | AP24: - Membantu Team Leader Membuat/menyusun dokumen lelang untuk pelaksanaan fisik. | BB24: - Membantu Team Leader Membuat/menyusun dokumen lelang untuk pelaksanaan fisik.
B25: f. Waktu Pelaksanaan | C25: Waktu Pelaksanaan | E25: : | F25: 04 Juli 2011 - 04 Oktober 2011 | N25: f. Waktu Pelaksanaan | O25: Waktu Pelaksanaan | Q25: : | R25: =F25 -> 04 Juli 2011 - 04 Oktober 2011 | Z25: f. Waktu Pelaksanaan | AA25: Waktu Pelaksanaan | AC25: : | AD25: =R25 -> 04 Juli 2011 - 04 Oktober 2011 | AL25: f. Waktu Pelaksanaan | AM25: Waktu Pelaksanaan | AO25: : | AP25: =AD25 -> 04 Juli 2011 - 04 Oktober 2011 | AX25: f. Waktu Pelaksanaan | AY25: Waktu Pelaksanaan | BA25: : | BB25: =AP25 -> 04 Juli 2011 - 04 Oktober 2011 | BJ25: f. Waktu Pelaksanaan | BK25: Waktu Pelaksanaan | BM25: :
B26: g. Posisi Penugasan | C26: Posisi Penugasan | E26: : | F26: Ketua Tim | N26: g. Posisi Penugasan | O26: Posisi Penugasan | Q26: : | R26: Ahli sipil | Z26: g. Posisi Penugasan | AA26: Posisi Penugasan | AC26: : | AD26: =AD4 -> Ahli Arsitektur | AL26: g. Posisi Penugasan | AM26: Posisi Penugasan | AO26: : | AP26: =AP4 -> Ahli Arsitektur | AX26: g. Posisi Penugasan | AY26: Posisi Penugasan | BA26: : | BB26: =AP26 -> Ahli Arsitektur | BJ26: g. Posisi Penugasan | BK26: Posisi Penugasan | BM26: :
B27: h. Status Kepegawaian pada Perusahaan | C27: Status Kepegawaian Pada Perusahaan | E27: : | F27: Tenaga Ahli Tetap | N27: h. Status Kepegawaian pada Perusahaan | O27: Status Kepegawaian Pada Perusahaan | Q27: : | R27: Tenaga Ahli Pendukung | Z27: h. Status Kepegawaian pada Perusahaan | AA27: Status Kepegawaian Pada Perusahaan | AC27: : | AD27: =R27 -> Tenaga Ahli Pendukung | AL27: h. Status Kepegawaian pada Perusahaan | AM27: Status Kepegawaian Pada Perusahaan | AO27: : | AP27: =AD27 -> Tenaga Ahli Pendukung | AX27: h. Status Kepegawaian pada Perusahaan | AY27: Status Kepegawaian Pada Perusahaan | BA27: : | BB27: =AP27 -> Tenaga Ahli Pendukung | BJ27: h. Status Kepegawaian pada Perusahaan | BK27: Status Kepegawaian Pada Perusahaan | BM27: :
B28: i. Surat Referensi dari Pengguna Jasa | C28: Surat Referensi dari Pengguna Jasa | E28: : | F28: Terlampir | N28: i. Surat Referensi dari Pengguna Jasa | O28: Surat Referensi dari Pengguna Jasa | Q28: : | R28: Terlampir | Z28: i. Surat Referensi dari Pengguna Jasa | AA28: Surat Referensi dari Pengguna Jasa | AC28: : | AD28: =R28 -> Terlampir | AL28: i. Surat Referensi dari Pengguna Jasa | AM28: Surat Referensi dari Pengguna Jasa | AO28: : | AP28: =AD28 -> Terlampir | AX28: i. Surat Referensi dari Pengguna Jasa | AY28: Surat Referensi dari Pengguna Jasa | BA28: : | BB28: =AP28 -> Terlampir | BJ28: i. Surat Referensi dari Pengguna Jasa | BK28: Surat Referensi dari Pengguna Jasa | BM28: :
B30: Tahun | D30: 2010 | N30: Tahun | P30: 2010 | Z30: Tahun | AB30: 2010 | AL30: Tahun | AN30: =AB30 -> 2010 | AX30: Tahun | AZ30: 2011 | BJ30: Tahun | BL30: 2011
B31: a. | C31: Nama Proyek | E31: : | F31: Perencanaan Data Base Jalan | N31: a. | O31: Nama Proyek | Q31: : | R31: =F31 -> Perencanaan Data Base Jalan | Z31: a. | AA31: Nama Proyek | AC31: : | AD31: =R31 -> Perencanaan Data Base Jalan | AL31: a. | AM31: Nama Proyek | AO31: : | AP31: =AD31 -> Perencanaan Data Base Jalan | AX31: a. | AY31: Nama Proyek | BA31: : | BB31: =AP31 -> Perencanaan Data Base Jalan | BJ31: a. | BK31: Nama Proyek | BM31: :
B32: b. Lokasi Proyek | C32: Lokasi Proyek | E32: : | F32: Kabupaten Sigi | N32: b. Lokasi Proyek | O32: Lokasi Proyek | Q32: : | R32: =F32 -> Kabupaten Sigi | Z32: b. Lokasi Proyek | AA32: Lokasi Proyek | AC32: : | AD32: =R32 -> Kabupaten Sigi | AL32: b. Lokasi Proyek | AM32: Lokasi Proyek | AO32: : | AP32: =AD32 -> Kabupaten Sigi | AX32: b. Lokasi Proyek | AY32: Lokasi Proyek | BA32: : | BB32: =AP32 -> Kabupaten Sigi | BJ32: b. Lokasi Proyek | BK32: Lokasi Proyek | BM32: :
B33: c. Pengguna Jasa | C33: Pengguna Jasa | E33: : | F33: Jasa Perencanaan | N33: c. Pengguna Jasa | O33: Pengguna Jasa | Q33: : | R33: =F33 -> Jasa Perencanaan | Z33: c. Pengguna Jasa | AA33: Pengguna Jasa | AC33: : | AD33: =R33 -> Jasa Perencanaan | AL33: c. Pengguna Jasa | AM33: Pengguna Jasa | AO33: : | AP33: =AD33 -> Jasa Perencanaan | AX33: c. Pengguna Jasa | AY33: Pengguna Jasa | BA33: : | BB33: =AP33 -> Jasa Perencanaan | BJ33: c. Pengguna Jasa | BK33: Pengguna Jasa | BM33: :
B34: d. Nama Perusahaan | C34: Nama Perusahaan | E34: : | F34: CV. Adicipta Nusatama | N34: d. Nama Perusahaan | O34: Nama Perusahaan | Q34: : | R34: =F34 -> CV. Adicipta Nusatama | Z34: d. Nama Perusahaan | AA34: Nama Perusahaan | AC34: : | AD34: =R34 -> CV. Adicipta Nusatama | AL34: d. Nama Perusahaan | AM34: Nama Perusahaan | AO34: : | AP34: =AD34 -> CV. Adicipta Nusatama | AX34: d. Nama Perusahaan | AY34: Nama Perusahaan | BA34: : | BB34: =AP34 -> CV. Adicipta Nusatama | BJ34: d. Nama Perusahaan | BK34: Nama Perusahaan | BM34: :
B35: e. | C35: Uraian Tugas | E35: : | F35: - Membuat dan menghitung desain struktur konstruksi yang kokoh namun ekonomis, | N35: =B35 -> e. | O35: Uraian Tugas | Q35: : | R35: - Bersama Team Leader membuat dan menghitung desain struktur konstruksi yang kokoh namun ekonomis, | Z35: =N35 -> e. | AA35: =O35 -> Uraian Tugas | AC35: : | AD35: - Bersama Team Leader membuat dan menghitung desain struktur konstruksi yang kokoh namun ekonomis, | AL35: e. Uraian Tugas | AM35: Uraian Tugas | AO35: : | AP35: - Bersama Team Leader membuat dan menghitung desain struktur konstruksi yang kokoh namun ekonomis, | AX35: e. Uraian Tugas | AY35: Uraian Tugas | BA35: : | BB35: - Bersama Team Leader membuat dan menghitung desain struktur konstruksi yang kokoh namun ekonomis, | BJ35: e. Uraian Tugas | BK35: Uraian Tugas | BM35: :
F36: - Melakukan asistensi kepada pemberi tugas terhadap desain yang telah dikerjakan, | R36: - Bersama Team Leader Melakukan asistensi kepada pemberi tugas terhadap desain yang telah dikerjakan, | AD36: - Bersama Team Leader Melakukan asistensi kepada pemberi tugas terhadap desain yang telah dikerjakan, | AP36: - Bersama Team Leader Melakukan asistensi kepada pemberi tugas terhadap desain yang telah dikerjakan, | BB36: - Bersama Team Leader Melakukan asistensi kepada pemberi tugas terhadap desain yang telah dikerjakan,
F37: - Membuat laporan maupun dokumen struktur lainnya, | R37: - Membantu Leader Membuat laporan maupun dokumen struktur lainnya, | AD37: - Membantu Leader Membuat laporan maupun dokumen struktur lainnya, | AP37: - Membantu Leader Membuat laporan maupun dokumen struktur lainnya, | BB37: - Membantu Leader Membuat laporan maupun dokumen struktur lainnya,
F38: - Bersama personil lainnya melakukan ekspose terhadap desain yang telah dihasilkan, | R38: - Bersama personil lainnya melakukan ekspose terhadap desain yang telah dihasilkan, | AD38: - Bersama personil lainnya melakukan ekspose terhadap desain yang telah dihasilkan, | AP38: - Bersama personil lainnya melakukan ekspose terhadap desain yang telah dihasilkan, | BB38: - Bersama personil lainnya melakukan ekspose terhadap desain yang telah dihasilkan,
F39: - Membuat/menyusun dokumen lelang untuk pelaksanaan fisik. | R39: - Membantu Team Leader Membuat/menyusun dokumen lelang untuk pelaksanaan fisik. | AD39: - Membantu Team Leader Membuat/menyusun dokumen lelang untuk pelaksanaan fisik. | AP39: - Membantu Team Leader Membuat/menyusun dokumen lelang untuk pelaksanaan fisik. | BB39: - Membantu Team Leader Membuat/menyusun dokumen lelang untuk pelaksanaan fisik.
B40: f. Waktu Pelaksanaan | C40: Waktu Pelaksanaan | E40: : | F40: 02 Nopember 2010 s/d 16 Desember 2010 | N40: f. Waktu Pelaksanaan | O40: Waktu Pelaksanaan | Q40: : | R40: =F40 -> 02 Nopember 2010 s/d 16 Desember 2010 | Z40: f. Waktu Pelaksanaan | AA40: Waktu Pelaksanaan | AC40: : | AD40: =R40 -> 02 Nopember 2010 s/d 16 Desember 2010 | AL40: f. Waktu Pelaksanaan | AM40: Waktu Pelaksanaan | AO40: : | AP40: =AD40 -> 02 Nopember 2010 s/d 16 Desember 2010 | AX40: f. Waktu Pelaksanaan | AY40: Waktu Pelaksanaan | BA40: : | BB40: =AP40 -> 02 Nopember 2010 s/d 16 Desember 2010 | BJ40: f. Waktu Pelaksanaan | BK40: Waktu Pelaksanaan | BM40: :
B41: g. Posisi Penugasan | C41: Posisi Penugasan | E41: : | F41: Ketua Tim | N41: g. Posisi Penugasan | O41: Posisi Penugasan | Q41: : | R41: =R26 -> Ahli sipil | Z41: g. Posisi Penugasan | AA41: Posisi Penugasan | AC41: : | AD41: =AD26 -> Ahli Arsitektur | AL41: g. Posisi Penugasan | AM41: Posisi Penugasan | AO41: : | AP41: =AP26 -> Ahli Arsitektur | AX41: g. Posisi Penugasan | AY41: Posisi Penugasan | BA41: : | BB41: =AP41 -> Ahli Arsitektur | BJ41: g. Posisi Penugasan | BK41: Posisi Penugasan | BM41: :
B42: h. Status Kepegawaian pada Perusahaan | C42: Status Kepegawaian Pada Perusahaan | E42: : | F42: Tenaga Ahli Tetap | N42: h. Status Kepegawaian pada Perusahaan | O42: Status Kepegawaian Pada Perusahaan | Q42: : | R42: =R27 -> Tenaga Ahli Pendukung | Z42: h. Status Kepegawaian pada Perusahaan | AA42: Status Kepegawaian Pada Perusahaan | AC42: : | AD42: =R42 -> Tenaga Ahli Pendukung | AL42: h. Status Kepegawaian pada Perusahaan | AM42: Status Kepegawaian Pada Perusahaan | AO42: : | AP42: =AD42 -> Tenaga Ahli Pendukung | AX42: h. Status Kepegawaian pada Perusahaan | AY42: Status Kepegawaian Pada Perusahaan | BA42: : | BB42: =AP42 -> Tenaga Ahli Pendukung | BJ42: h. Status Kepegawaian pada Perusahaan | BK42: Status Kepegawaian Pada Perusahaan | BM42: :
B43: i. Surat Referensi dari Pengguna Jasa | C43: Surat Referensi dari Pengguna Jasa | E43: : | F43: =F28 -> Terlampir | N43: i. Surat Referensi dari Pengguna Jasa | O43: Surat Referensi dari Pengguna Jasa | Q43: : | R43: =R28 -> Terlampir | Z43: i. Surat Referensi dari Pengguna Jasa | AA43: Surat Referensi dari Pengguna Jasa | AC43: : | AD43: =R43 -> Terlampir | AL43: i. Surat Referensi dari Pengguna Jasa | AM43: Surat Referensi dari Pengguna Jasa | AO43: : | AP43: =AD43 -> Terlampir | AX43: i. Surat Referensi dari Pengguna Jasa | AY43: Surat Referensi dari Pengguna Jasa | BA43: : | BB43: =AP43 -> Terlampir | BJ43: i. Surat Referensi dari Pengguna Jasa | BK43: Surat Referensi dari Pengguna Jasa | BM43: :
...

Sheet pernyataan kesediaan
A1: PERNYATAAN KESEDIAAN UNTUK DITUGASKAN
A3: Yang Bertanda tangan di bawah ini :
A4: Nama | C4: : | D4: =J24 -> Ir.Fatmawati
A5: Alamat | C5: : | D5: Pasangkayu, Kab Mamuju Utara
A7: Dengan ini menyatakan bahwa saya bersedia untuk melaksanakan paket pekerjaan jasa konsultansi Perencanaan Peningkatan Pelabuhan Ako – Salule untuk Penyedia Jasa Konsultansi CV.TOHA PRATAMA sesuai dengan usulan jadwal penugasan saya dari bulan Februari tahun 2015 dengan posisi sebagai tenaga ahli Team Leader.
A13: Demikian pernyataan ini saya buat dengan sebenar-benarnya dan penuh rasa tanggung jawab.
I17: Pasangkayu, 13 Februari 2015
J18: Yang Membuat
J19: Pernyataan
I24: ( | J24: Ir.Fatmawati | O24: )
A27: Menyetujui :
C28: CV. TOHA PRATAMA
C33: ANDI NUR FAISAL, ST
C34: ='Daftar Pengalaman Kerja'!G81 -> Direktur
A36: PERNYATAAN KESEDIAAN UNTUK DITUGASKAN
A38: Yang Bertanda tangan di bawah ini :
A39: Nama | C39: : | D39: Deddy Sanjaya Rioeh,ST
A40: Alamat | C40: : | D40: Kemas Somad RT.18/RW.02 No.99 Kel.Kenali Besar Kec.Kota
D41: Baru Kota Jambi
A42: Dengan ini menyatakan bahwa saya bersedia untuk melaksanakan paket pekerjaan jasa konsultansi Perencanaan Peningkatan Pelabuhan Ako – Salule untuk Penyedia Jasa Konsultansi CV.TOHA PRATAMA sesuai dengan usulan jadwal penugasan saya dari bulan Februari tahun 2015 dengan posisi sebagai tenaga ahli Ahli Sipil Transportasi.
A50: Demikian pernyataan ini saya buat dengan sebenar-benarnya dan penuh rasa tanggung jawab.
I54: Pasangkayu, 13 Februari 2015
J55: Yang Membuat
J56: Pernyataan
I61: ( | J61: =D39 -> Deddy Sanjaya Rioeh,ST | O61: )
A64: Menyetujui :
C65: CV. TOHA PRATAMA
C70: ANDI NUR FAISAL, ST
C71: =C34 -> Direktur
A73: PERNYATAAN KESEDIAAN UNTUK DITUGASKAN
A75: Yang Bertanda tangan di bawah ini :
A76: Nama | C76: :
A77: Alamat | C77: :
A79: Dengan ini menyatakan bahwa saya bersedia untuk melaksanakan paket pekerjaan jasa konsultansi _____________ untuk Penyedia Jasa Konsultansi _____________ sesuai dengan usulan jadwal penugasan saya dari bulan __________ tahun __________ sampai dengan bulan__________ tahun __________ dengan posisi sebagai tenaga ahli _________________.
A87: Demikian pernyataan ini saya buat dengan sebenar-benarnya dan penuh rasa tanggung jawab.
I91: Pasangkayu, April 2012
J92: Yang Membuat
J93: Pernyataan
I98: ( | O98: )
A101: Menyetujui :
...

Sheet S. Pnwrn Biaya
I6: Pasangkayu, April 2012
A7: Nomor | C7: : | D7: 04/PNWR-KONT/TPU/X/2012
A8: Lampiran | C8: : | D8: 1 (Satu) Berkas
A10: Kepada Yth
A11: Pokja Jasa Konstruksi ULP Kab. Mamuju Utara
A12: di
B13: Pasangkayu
A15: Perihal : | C15: Penawaran Administrasi dan Teknis “Perencanaan Peningkatan Hotmix Jalan Poros Trans dan Perecanaan Peningkatan Hotmix Jalan Malei Desa Pedanda 1”
A19: Sehubungan dengan Undangan Pengambilan Dokumen Pemilihan Nomor P.0004.a/UND-DP/PU/ULP-JKJL/IV/2012 tanggal 17 April 2012 dan setelah kami pelajari dengan saksama Dokumen Pemilihan, Berita Acara Pemberian Penjelasan Adendum Dokumen Perencanaan, serta menunjuk Surat Penawaran Administrasi dan Teknis kami nomor 03/PNWR-KONT/TPU/X/2012 perihal Penawaran Administrasi dan Teknis Penawaran Administrasi dan Teknis “Perencanaan Peningkatan Hotmix Jalan Poros Trans dan Perecanaan Peningkatan Hotmix Jalan Malei Desa Pedanda 1” , dengan ini kami mengajukan Penawaran Biaya untuk pekerjaan “Perencanaan Peningkatan Hotmix Jalan Poros Trans dan Perecanaan Peningkatan Hotmix Jalan Malei Desa Pedanda 1” sebesar Rp. ______________ (____________________________).
A20: Penawaran Biaya ini sudah memperhatikan ketentuan dan persyaratan yang tercantum dalam Dokumen Pemilihan untuk melaksanakan pekerjaan tersebut di atas. Jangka waktu pelaksanaan pekerjaan selama 30 (Tiga Puluh) hari kalender.
A21: Penawaran ini berlaku selama 14 (Empat Belas) hari kalender sejak pembukaan Dokumen Penawaran.
A22: Sesuai dengan persyaratan Dokumen Pemilihan, bersama Surat Penawaran Biaya ini kami lampirkan :
A23: 1 | B23: Rekapitulasi Penawaran Biaya
A24: 2 | B24: Rincian Biaya Langsung Personil (remuneration)
A25: 3 | B25: Rincian Biaya Langsung Non-Personil (direct reimburseable cost)
A27: Dengan disampaikannya Surat Penawaran ini, maka kami menyatakan sanggup dan akan tunduk pada semua ketentuan yang tercantum dalam Dokumen Pemilihan.
M29: ='pernyataan kesediaan'!C176 -> CV. TOHA PRATAMA
M34: ='pernyataan kesediaan'!C181 -> ANDI NUR FAISAL, ST
M35: ='pernyataan kesediaan'!C182 -> Direktur

Sheet Rekapitulasi Pnwrn Biaya
A2: Rekapitulasi Penawaran Biaya
A4: No | B4: Uraian | C4: Total Harga
C5: (Rp)
A6: I | B6: Biaya Langsung Personil
A7: II | B7: Biaya Langsung Non - Personil
B8: Sub-total
B9: PPN 10 %
B10: Total
A11: Trebilang :

Sheet R. Biaya Langsung Personil
A1: Rincian Biaya Langsung Personil (remuneration)
A3: Nama Personil | B3: Posisi | C3: Harga Satuan | D3: Orang Bulan | E3: Jumlah (Rp)
C4: Orang Bulan
C5: (Rp)
A6: Nasional
A12: Nasional
A15: Total Biaya

Sheet R. Biaya Langsung Non-Personil
A1: Rincian Biaya Langsung Non-Personil (direct reimburseable cost)
A3: Jenis Biaya | B3: Uraian Biaya | C3: Satuan (hari/kali) | D3: Biaya-biaya | F3: Jumlah (Rp)
D4: Harga Satuan (Rp) | E4: Lump Sum (Rp)
A6: Biaya Kantor | B6: Biaya Sewa Kantor
B7: Biaya Pemeliharaan Kantor
B8: Biaya Komunikasi
B9: Biaya Peralatan Kantor
B10: Biaya Kantor Lainnya
A11: Biaya Perjalanan Dinas | B11: Biaya Tiket
B12: Uang Harian
B13: Perjalanan Darat
B14: Biaya Perjalanan Dinas lainnya
A15: Biaya Laporan | B15: Laporan Pendahuluan
B16: Laporan Antara
B17: Laporan Akhir
B18: Laporan Penyelenggaraan Seminar
B19: Biaya Laporan Lainnya
A20: Biaya Lainnya
A21: Total Biaya
